Workbook
Name taper_rate: 'DCF Model'!$C$17
Name Tax_rate: 'DCF Model'!$C$21

Sheet FSA
A1: 99 SpeedMart Financial Statement Analysis
B2: 2025 | C2: 2024 | D2: 2023 | E2: 2022 | F2: 2021
A3: P/L Statement | E3: in MYR (Millions)
A4: Sales/Revenue | B4: 11433 | C4: 9982 | D4: 9214 | E4: 8075 | F4: 7837
A5: Cost of Goods Sold (COGS) incl. D&A | B5: 10412 | C5: 9124 | D5: 8407 | E5: 7543 | F5: 7270
A6: Gross Income | B6: 1022 | C6: 858 | D6: 807 | E6: 532 | F6: 566
A7: SG&A Expense (include D&A) | B7: 1154 | C7: 999 | D7: 912 | E7: 762 | F7: 658
A8: EBIT | B8: -132 | C8: -142 | D8: -105 | E8: -230 | F8: -92
A9: Non Operating Income/Expense | B9: 993 | C9: 844 | D9: 687 | E9: 762 | F9: 703
A10: Interest Expense | B10: 48 | C10: 45 | D10: 44 | E10: 52 | F10: 53
A11: Pretax Income | B11: 814 | C11: 659 | D11: 538 | E11: 484 | F11: 562
A12: Income Tax | B12: 199 | C12: 168 | D12: 138 | E12: 157 | F12: 143
A13: Net Income | B13: 614 | C13: 490 | D13: 400 | E13: 327 | F13: 419
A15: Balance Sheet
A16: Assets
A17: Cash & Short Term Investments | B17: 898 | C17: 698 | D17: 138 | E17: 85 | F17: 350
A18: Total Accounts Receivable | B18: 45 | C18: 20 | D18: 44 | E18: 29 | F18: 18
A19: Inventories | B19: 1450 | C19: 1339 | D19: 1174 | E19: 1093 | F19: 803
A20: Other Current Assets | B20: 60 | C20: 49 | D20: 40 | E20: 36 | F20: 43
A21: Total Current Assets | B21: 2452 | C21: 2106 | D21: 1396 | E21: 1243 | F21: 1215
A22: Net Property, Plant & Equipment | B22: 1615 | C22: 1442 | D22: 1254 | E22: 1122 | F22: 1131
A23: Intangible Assets | B23: 0 | C23: 0 | D23: 0 | E23: 0 | F23: 0
A24: Total Assets | B24: 4076 | C24: 3761 | D24: 2839 | E24: 2380 | F24: 2358
A26: Liabilities
A27: ST Debt & Current Portion LT Debt | B27: 196 | C27: 176 | D27: 160 | E27: 141 | F27: 126
A28: Accounts Payable | B28: 1120 | C28: 936 | D28: 982 | E28: 805 | F28: 640
A29: Income Tax Payable | B29: 21 | C29: 25 | D29: 28 | E29: 29 | F29: 30
A30: Other Current Liabilities | B30: 81 | C30: 74 | D30: 222 | E30: 70 | F30: 66
A31: Total Current Liabilities | B31: 1419 | C31: 1212 | D31: 1391 | E31: 1045 | F31: 862
A32: Long-Term Debt | B32: 778 | C32: 712 | D32: 680 | E32: 656 | F32: 716
A33: Other Long-Term Liabilities (Provisions/Deferred Taxes) | B33: 56 | C33: 46 | D33: 37 | E33: 32 | F33: 31
A34: Total Liabilities | B34: 2261 | C34: 2182 | D34: 2298 | E34: 1749 | F34: 1621
A36: Shareholders' Equity
A37: Common Equity (Total) | B37: 1815 | C37: 1579 | D37: 542 | E37: 632 | F37: 737
A38: Liabilities & Shareholders' Equity | B38: 4076 | C38: 3761 | D38: 2839 | E38: 2380 | F38: 2358
A41: Horizontol Analysis
A42: P/L Statement | E42: in MYR (Millions)
A43: Sales/Revenue | B43: =B4/B$4 -> 1 | C43: =C4/C$4 -> 1 | D43: =D4/D$4 -> 1 | E43: =E4/E$4 -> 1 | F43: =F4/F$4 -> 1
A44: Cost of Goods Sold (COGS) incl. D&A | B44: =B5/B$4 -> 0.9106971 | C44: =C5/C$4 -> 0.91404528 | D44: =D5/D$4 -> 0.91241589 | E44: =E5/E$4 -> 0.93411765 | F44: =F5/F$4 -> 0.92765089
A45: Gross Income | B45: =B6/B$4 -> 0.089390361 | C45: =C6/C$4 -> 0.085954718 | D45: =D6/D$4 -> 0.087584111 | E45: =E6/E$4 -> 0.065882353 | F45: =F6/F$4 -> 0.072221513
...

Sheet DCF Model
B1: Discounted Cash Flow (DCF)
B4: Company Overview
B6: 99 Speedmart is a retail chain, specifically a mini-supermarket chain focusing on groceries and daily neccessities
B8: Total Store Count: 3,000+ outlets across Malaysia
B11: Key Assumptions & Methodology
B13: Parameter | C13: Value | D13: Rationale
B14: Valuation Date
B15: Projection Period
B16: Revenue Growth% | C16: 0.09 | D16: Top-down industry trends (retail sector growing at 7.0%, + market leader premium)
B17: Annual Growth Tapering | C17: 0.01
B18: Terminal Growth Rate | C18: 0.02 | D18: Conservative long-term growth
B19: Risk-Free Rate (Rf) | C19: 0.035 | D19: Malaysian 10-Year Government Bond Yield
B20: Equity Risk Premium (ERP) | C20: 0.0578 | D20: Expected return over risk-free rate for invetors
B21: Tax Rate | C21: 0.24 | D21: Effective tax rate based on historical data
B24: Financial Performance (RM Million)
B26: Income Statement
B27: Particulars | C27: 2025 | D27: 2024 | E27: 2023 | F27: 2022 | G27: 2021
B28: Sales | C28: =Data!B4 -> 11433 | D28: =Data!C4 -> 9982 | E28: =Data!D4 -> 9214 | F28: =Data!E4 -> 8075 | G28: =Data!F4 -> 7837
B29: % growth | C29: =C28/D28-1 -> 0.14536165 | D29: =D28/E28-1 -> 0.083351422 | E29: =E28/F28-1 -> 0.14105263 | F29: =F28/G28-1 -> 0.030368764
B30: Cost of Goods Sold | C30: =Data!B7 -> 10135 | D30: =Data!C7 -> 8877 | E30: =Data!D7 -> 8185 | F30: =Data!E7 -> 7334 | G30: =Data!F7 -> 7081
B31: % of revenue | C31: =C30/C28 -> 0.88646899 | D31: =D30/D28 -> 0.88930074 | E31: =E30/E28 -> 0.88832212 | F31: =F30/F28 -> 0.90823529 | G31: =G30/G28 -> 0.90353452
B32: Gross Profit | C32: =Data!B12+Data!B8 -> 1299 | D32: =Data!C12+Data!C8 -> 1105 | E32: =Data!D12+Data!D8 -> 1030 | F32: =Data!E12+Data!E8 -> 741 | G32: =Data!F12+Data!F8 -> 756
B33: % margin | C33: =C32/C28 -> 0.11361847 | D33: =D32/D28 -> 0.11069926 | E33: =E32/E28 -> 0.11178641 | F33: =F32/F28 -> 0.091764706 | G33: =G32/G28 -> 0.096465484
B34: Operating Expenses | C34: =Data!B16 -> 1154 | D34: =Data!C16 -> 999 | E34: =Data!D16 -> 912 | F34: =Data!E16 -> 762 | G34: =Data!F16 -> 658
B35: % of revenue | C35: =C34/C28 -> 0.10093589 | D35: =D34/D28 -> 0.10008014 | E35: =E34/E28 -> 0.098979813 | F35: =F34/F28 -> 0.094365325 | G35: =G34/G28 -> 0.083960699
B36: EBITDA | C36: =C32-C34 -> 145 | D36: =D32-D34 -> 106 | E36: =E32-E34 -> 118 | F36: =F32-F34 -> -21 | G36: =G32-G34 -> 98
B37: % margin | C37: =C36/C28 -> 0.012682585 | D37: =D36/D28 -> 0.010619114 | E37: =E36/E28 -> 0.012806599 | F37: =F36/F28 -> -0.0026006192 | G37: =G36/G28 -> 0.012504785
B38: Depreciation | C38: =Data!B9 -> 277 | D38: =Data!C9 -> 247 | E38: =Data!D9 -> 223 | F38: =Data!E9 -> 209 | G38: =Data!F9 -> 190
B39: % of net sales | C39: =C38/C28 -> 0.024228112 | D39: =D38/D28 -> 0.02474454 | E39: =E38/E28 -> 0.024202301 | F39: =F38/F28 -> 0.025882353 | G39: =G38/G28 -> 0.024243971
B40: EBIT | C40: =C36-C38+Data!B21 -> -132 | D40: =D36-D38+Data!C21 -> -142 | E40: =E36-E38+Data!D21 -> -105 | F40: =F36-F38+Data!E21 -> -230 | G40: =G36-G38+Data!F21 -> -92
B41: % margin | C41: =C40/C28 -> -0.011545526 | D41: =D40/D28 -> -0.014225606 | E41: =E40/E28 -> -0.011395702 | F41: =F40/F28 -> -0.028482972 | G41: =G40/G28 -> -0.011739186
B42: Other Income | C42: =Data!B23 -> 993 | D42: =Data!C23 -> 844 | E42: =Data!D23 -> 687 | F42: =Data!E23 -> 762 | G42: =Data!F23 -> 703
B43: Interest | C43: =Data!B25 -> 48 | D43: =Data!C25 -> 45 | E43: =Data!D25 -> 44 | F43: =Data!E25 -> 52 | G43: =Data!F25 -> 53
B44: % of debt | C44: =C43/Data!B100 -> 0.24489796 | D44: =D43/Data!C100 -> 0.25568182 | E44: =E43/Data!D100 -> 0.275 | F44: =F43/Data!E100 -> 0.36879433 | G44: =G43/Data!F100 -> 0.42063492
B45: Profit before tax | C45: =Data!B29 -> 814 | D45: =Data!C29 -> 659 | E45: =Data!D29 -> 538 | F45: =Data!E29 -> 484 | G45: =Data!F29 -> 562
B46: % of revenue | C46: =C45/C28 -> 0.071197411 | D46: =D45/D28 -> 0.066018834 | E46: =E45/E28 -> 0.058389407 | F46: =F45/F28 -> 0.05993808 | G46: =G45/G28 -> 0.071711114
B47: Tax | C47: =Data!B33 -> 199 | D47: =Data!C33 -> 168 | E47: =Data!D33 -> 138 | F47: =Data!E33 -> 157 | G47: =Data!F33 -> 143
B48: % of PBT | C48: =C47/C45 -> 0.24447174 | D48: =D47/D45 -> 0.25493171 | E48: =E47/E45 -> 0.25650558 | F48: =F47/F45 -> 0.32438017 | G48: =G47/G45 -> 0.2544484
B49: Net profit | C49: =Data!B38 -> 614 | D49: =Data!C38 -> 490 | E49: =Data!D38 -> 400 | F49: =Data!E38 -> 327 | G49: =Data!F38 -> 419
B50: % of revenue | C50: =C49/C28 -> 0.05370419 | D50: =D49/D28 -> 0.049088359 | E50: =E49/E28 -> 0.043412199 | F50: =F49/F28 -> 0.040495356 | G50: =G49/G28 -> 0.053464336
...

Sheet Comps 
B4: Comps Data (Million)
B6: Company | C6: Ticker | D6: Price | E6: Market Cap | F6: Sales | G6: EBITDA | H6: Net Income | I6: Beta | J6: Total Debt | K6: Cash & Cash Equivalents | L6: EV/EBITDA | M6: P/E
B7: 99 Speed Mart Retail Holdings Berhad | C7: 5326.KL | D7: 3.5 | E7: 28980 | F7: 11433 | G7: 888 | H7: 614 | I7: 1.22 | J7: 974 | K7: 897 | L7: 199.99 | M7: 43.88
B8: Eco-Shop Marketing Berhad | C8: 5296.KL | D8: 1.57 | E8: 9090 | F8: 2790 | G8: 442 | H8: 231 | I8: 0.06 | J8: 446 | K8: 248 | L8: 21.02 | M8: 39.21
B9: AEON Co. (Malaysia) Bhd. | C9: 6599.KL | D9: 1.17 | E9: 1680 | F9: 4290 | G9: 741 | H9: 113 | I9: 0.88 | J9: 2410 | K9: 354 | L9: 4.83 | M9: 14.75
B10: 7-Eleven Malaysia Holdings Bhd | C10: 5250.KL | D10: 1.99 | E10: 2120 | F10: 3180 | G10: 158 | H10: 32 | I10: -0.06 | J10: 1370 | K10: 105 | L10: 21.89 | M10: 68.75
B11: CCK Consolidated Holdings Bhd. | C11: 7035.KL | D11: 1.22 | E11: 783 | F11: 1050 | G11: 221 | H11: 67 | I11: 0.55 | J11: 80 | K11: 235 | L11: 2.93 | M11: 11.03
B14: Industry Beta
C16: Equity | D16: Total | E16: Debt/ | F16: Debt/ | G16: Tax | H16: Levered | I16: Unlevered
B17: Company Name | C17: Value | D17: Debt | E17: Equity | F17: Capital | G17: Rate % | H17: Beta | I17: Beta
B18: Eco-Shop Marketing Berhad | C18: =E8 -> 9090 | D18: =J8 -> 446 | E18: =D18/C18 -> 0.049064906 | F18: =D18/(C18+D18) -> 0.046770134 | G18: =Tax_rate -> 0.24 | H18: =I8 -> 0.06 | I18: =H18/(1+E18*(1-G18)) -> 0.057843071
B19: AEON Co. (Malaysia) Bhd. | C19: =E9 -> 1680 | D19: =J9 -> 2410 | E19: =D19/C19 -> 1.4345238 | F19: =D19/(C19+D19) -> 0.58924205 | G19: =Tax_rate -> 0.24 | H19: =I9 -> 0.88 | I19: =H19/(1+E19*(1-G19)) -> 0.42100467
B20: 7-Eleven Malaysia Holdings Bhd | C20: =E10 -> 2120 | D20: =J10 -> 1370 | E20: =D20/C20 -> 0.64622642 | F20: =D20/(C20+D20) -> 0.39255014 | G20: =Tax_rate -> 0.24 | H20: =I10 -> -0.06 | I20: =H20/(1+E20*(1-G20)) -> -0.040237884
B21: CCK Consolidated Holdings Bhd. | C21: =E11 -> 783 | D21: =J11 -> 80 | E21: =D21/C21 -> 0.10217114 | F21: =D21/(C21+D21) -> 0.092699884 | G21: =Tax_rate -> 0.24 | H21: =I11 -> 0.55 | I21: =H21/(1+E21*(1-G21)) -> 0.51036976
B22: Average | E22: =AVERAGE(E18:E21) -> 0.55799657 | F22: =AVERAGE(F18:F21) -> 0.28031555 | G22: =AVERAGE(G18:G21) -> 0.24 | H22: =AVERAGE(H18:H21) -> 0.3575 | I22: =AVERAGE(I18:I21) -> 0.2372449
B23: Median | E23: =MEDIAN(E18:E21) -> 0.37419878 | F23: =MEDIAN(F18:F21) -> 0.24262501 | G23: =MEDIAN(G18:G21) -> 0.24 | H23: =MEDIAN(H18:H21) -> 0.305 | I23: =MEDIAN(I18:I21) -> 0.23942387

Sheet Data
A2: Income Statement
A3: Fiscal year is January-December. All values MYR Millions. | B3: 2025 | C3: 2024 | D3: 2023 | E3: 2022 | F3: 2021
A4: Sales/Revenue | B4: 11433 | C4: 9982 | D4: 9214 | E4: 8075 | F4: 7837
A5: Sales Growth | B5: 0.1454 | C5: 0.0833 | D5: 0.141 | E5: 0.0304 | F5: -
A6: Cost of Goods Sold (COGS) incl. D&A | B6: 10412 | C6: 9124 | D6: 8407 | E6: 7543 | F6: 7270
A7: COGS excluding D&A | B7: 10135 | C7: 8877 | D7: 8185 | E7: 7334 | F7: 7081
A8: Depreciation & Amortization Expense | B8: 277 | C8: 247 | D8: 223 | E8: 209 | F8: 190
A9: Depreciation | B9: 277 | C9: 247 | D9: 223 | E9: 209 | F9: 190
A10: Amortization of Intangibles | B10: 0 | C10: 0 | D10: - | E10: 0 | F10: 0
A11: COGS Growth | B11: 0.1411 | C11: 0.0852 | D11: 0.1145 | E11: 0.0376 | F11: -
A12: Gross Income | B12: 1022 | C12: 858 | D12: 807 | E12: 532 | F12: 566
A13: Gross Income Growth | B13: 0.191 | C13: 0.0632 | D13: 0.517 | E13: -0.0609 | F13: -
A15: Gross Profit Margin | B15: 0.0894 | C15: - | D15: - | E15: - | F15: -
A16: SG&A Expense | B16: 1154 | C16: 999 | D16: 912 | E16: 762 | F16: 658
A17: Other SG&A | B17: 1154 | C17: 999 | D17: 912 | E17: 762 | F17: 658
A18: SGA Growth | B18: 0.1543 | C18: 0.0963 | D18: 0.197 | E18: 0.1564 | F18: -
A19: EBIT | B19: -132 | C19: -142 | D19: -105 | E19: -230 | F19: -92
A21: Unusual Expense | B21: 0 | C21: -1 | D21: 0 | E21: 0 | F21: 0
A23: Non Operating Income/Expense | B23: 993 | C23: 844 | D23: 687 | E23: 762 | F23: 703
A24: Non-Operating Interest Income | B24: - | C24: - | D24: - | E24: 3 | F24: 5
A25: Interest Expense | B25: 48 | C25: 45 | D25: 44 | E25: 52 | F25: 53
A26: Interest Expense Growth | B26: 0.0639 | C26: 0.0228 | D26: -0.1459 | E26: -0.0326 | F26: -
A28: Gross Interest Expense | B28: 48 | C28: 45 | D28: 44 | E28: 52 | F28: 53
A29: Pretax Income | B29: 814 | C29: 659 | D29: 538 | E29: 484 | F29: 562
A30: Pretax Income Growth | B30: 0.2353 | C30: 0.2237 | D30: 0.1117 | E30: -0.1383 | F30: -
A32: Pretax Margin | B32: 0.0712 | C32: - | D32: - | E32: - | F32: -
A33: Income Tax | B33: 199 | C33: 168 | D33: 138 | E33: 157 | F33: 143
A34: Income Tax - Current Domestic | B34: - | C34: 165 | D34: 139 | E34: 161 | F34: 148
A35: Income Tax - Deferred Domestic | B35: - | C35: 4 | D35: -1 | E35: -4 | F35: -5
A37: Consolidated Net Income | B37: 614 | C37: 490 | D37: 400 | E37: 327 | F37: 419
A38: Net Income | B38: 614 | C38: 490 | D38: 400 | E38: 327 | F38: 419
A39: Net Income Growth | B39: 0.2528 | C39: 0.225 | D39: 0.2252 | E39: -0.2205 | F39: -
A41: Net Margin | B41: 0.0537 | C41: - | D41: - | E41: - | F41: -
A42: Net Income After Extraordinaries | B42: 614 | C42: 490 | D42: 400 | E42: 327 | F42: 419
A43: Net Income Available to Common | B43: 614 | C43: 490 | D43: 400 | E43: 327 | F43: 419
A44: EPS (Basic) | B44: 0.07 | C44: 0.06 | D44: 0.05 | E44: 0.04 | F44: 0.05
A45: EPS (Basic) Growth | B45: 0.2286 | C45: 0.25 | D45: 0.2237 | E45: -0.2204 | F45: -
A47: Basic Shares Outstanding | B47: 8400 | C47: 8246 | D47: 8400 | E47: 8400 | F47: 8400
A48: EPS (Diluted) | B48: - | C48: 0.06 | D48: 0.05 | E48: 0.04 | F48: 0.05
A49: EPS (Diluted) Growth | B49: 0 | C49: 0.2479 | D49: 0.2252 | E49: -0.2205 | F49: -
...
